Traceback (most recent call last):
  File "/opt/homebrew/Caskroom/miniforge/base/lib/python3.10/site-packages/jupyter_cache/executors/utils.py", line 58, in single_nb_execution
    executenb(
  File "/opt/homebrew/Caskroom/miniforge/base/lib/python3.10/site-packages/nbclient/client.py", line 1314, in execute
    return NotebookClient(nb=nb, resources=resources, km=km, **kwargs).execute()
  File "/opt/homebrew/Caskroom/miniforge/base/lib/python3.10/site-packages/jupyter_core/utils/__init__.py", line 173, in wrapped
    return loop.run_until_complete(inner)
  File "/opt/homebrew/Caskroom/miniforge/base/lib/python3.10/asyncio/base_events.py", line 649, in run_until_complete
    return future.result()
  File "/opt/homebrew/Caskroom/miniforge/base/lib/python3.10/site-packages/nbclient/client.py", line 709, in async_execute
    await self.async_execute_cell(
  File "/opt/homebrew/Caskroom/miniforge/base/lib/python3.10/site-packages/nbclient/client.py", line 1062, in async_execute_cell
    await self._check_raise_for_error(cell, cell_index, exec_reply)
  File "/opt/homebrew/Caskroom/miniforge/base/lib/python3.10/site-packages/nbclient/client.py", line 918, in _check_raise_for_error
    raise CellExecutionError.from_cell_and_msg(cell, exec_reply_content)
nbclient.exceptions.CellExecutionError: An error occurred while executing the following cell:
------------------
np.linalg.norm(SparsePauliOp.from_sparse_list([('Z', [i], 1) for i in range(0, n)], n), ord=2)
------------------


[0;31m---------------------------------------------------------------------------[0m
[0;31mNameError[0m                                 Traceback (most recent call last)
Cell [0;32mIn[3], line 1[0m
[0;32m----> 1[0m np[38;5;241m.[39mlinalg[38;5;241m.[39mnorm(SparsePauliOp[38;5;241m.[39mfrom_sparse_list([([38;5;124m'[39m[38;5;124mZ[39m[38;5;124m'[39m, [i], [38;5;241m1[39m) [38;5;28;01mfor[39;00m i [38;5;129;01min[39;00m [38;5;28mrange[39m([38;5;241m0[39m, [43mn[49m)], n), [38;5;28mord[39m[38;5;241m=[39m[38;5;241m2[39m)

[0;31mNameError[0m: name 'n' is not defined

